<?xml version="1.0" ?>
<robot name="diff_H80" xmlns:xacro="http://www.ros.org/wiki/xacro">

<xacro:include filename="$(find diff_H80_description)/urdf/materials.xacro" />
<xacro:include filename="$(find diff_H80_description)/urdf/diff_H80.trans" />
<xacro:include filename="$(find diff_H80_description)/urdf/diff_H80.gazebo" />
<link name="base_link">
  <inertial>
    <origin xyz="-0.0007097470847777941 0.1606544159292186 -6.0780571919646865e-05" rpy="0 0 0"/>
    <mass value="3.422105761645047"/>
    <inertia ixx="0.102447" iyy="0.239163" izz="0.185501" ixy="0.000207" iyz="1.8e-05" ixz="5.8e-05"/>
  </inertial>
  <visual>
    <origin xyz="0 0 0" rpy="0 0 0"/>
    <geometry>
      <mesh filename="package://diff_H80_description/meshes/base_link.stl" scale="0.001 0.001 0.001"/>
    </geometry>
    <material name="silver"/>
  </visual>
  <collision>
    <origin xyz="0 0 0" rpy="0 0 0"/>
    <geometry>
      <mesh filename="package://diff_H80_description/meshes/base_link.stl" scale="0.001 0.001 0.001"/>
    </geometry>
  </collision>
</link>

<link name="wheel_1">
  <inertial>
    <origin xyz="4.939911341095282e-09 2.2610133487699358e-08 0.05271472714665093" rpy="0 0 0"/>
    <mass value="2.9832346042890965"/>
    <inertia ixx="0.015656" iyy="0.015719" izz="0.02856" ixy="-0.0" iyz="0.0" ixz="-0.0"/>
  </inertial>
  <visual>
    <origin xyz="0.2 -0.13 -0.2" rpy="0 0 0"/>
    <geometry>
      <mesh filename="package://diff_H80_description/meshes/wheel_1.stl" scale="0.001 0.001 0.001"/>
    </geometry>
    <material name="silver"/>
  </visual>
  <collision>
    <origin xyz="0.2 -0.13 -0.2" rpy="0 0 0"/>
    <geometry>
      <mesh filename="package://diff_H80_description/meshes/wheel_1.stl" scale="0.001 0.001 0.001"/>
    </geometry>
  </collision>
</link>

<link name="wheel_2">
  <inertial>
    <origin xyz="4.939911507628736e-09 2.2610133487699358e-08 0.05271472714665093" rpy="0 0 0"/>
    <mass value="2.9832346042890965"/>
    <inertia ixx="0.015656" iyy="0.015719" izz="0.02856" ixy="-0.0" iyz="0.0" ixz="-0.0"/>
  </inertial>
  <visual>
    <origin xyz="-0.2 -0.13 -0.2" rpy="0 0 0"/>
    <geometry>
      <mesh filename="package://diff_H80_description/meshes/wheel_2.stl" scale="0.001 0.001 0.001"/>
    </geometry>
    <material name="silver"/>
  </visual>
  <collision>
    <origin xyz="-0.2 -0.13 -0.2" rpy="0 0 0"/>
    <geometry>
      <mesh filename="package://diff_H80_description/meshes/wheel_2.stl" scale="0.001 0.001 0.001"/>
    </geometry>
  </collision>
</link>

<link name="wheel_4">
  <inertial>
    <origin xyz="4.939911507628736e-09 -2.2610133459943782e-08 -0.05271472714665093" rpy="0 0 0"/>
    <mass value="2.9832346042890965"/>
    <inertia ixx="0.015656" iyy="0.015719" izz="0.02856" ixy="0.0" iyz="0.0" ixz="0.0"/>
  </inertial>
  <visual>
    <origin xyz="-0.2 -0.13 0.2" rpy="0 0 0"/>
    <geometry>
      <mesh filename="package://diff_H80_description/meshes/wheel_4.stl" scale="0.001 0.001 0.001"/>
    </geometry>
    <material name="silver"/>
  </visual>
  <collision>
    <origin xyz="-0.2 -0.13 0.2" rpy="0 0 0"/>
    <geometry>
      <mesh filename="package://diff_H80_description/meshes/wheel_4.stl" scale="0.001 0.001 0.001"/>
    </geometry>
  </collision>
</link>

<link name="wheel_3">
  <inertial>
    <origin xyz="4.939911341095282e-09 -2.2610133459943782e-08 -0.05271472714665093" rpy="0 0 0"/>
    <mass value="2.9832346042890965"/>
    <inertia ixx="0.015656" iyy="0.015719" izz="0.02856" ixy="0.0" iyz="0.0" ixz="0.0"/>
  </inertial>
  <visual>
    <origin xyz="0.2 -0.13 0.2" rpy="0 0 0"/>
    <geometry>
      <mesh filename="package://diff_H80_description/meshes/wheel_3.stl" scale="0.001 0.001 0.001"/>
    </geometry>
    <material name="silver"/>
  </visual>
  <collision>
    <origin xyz="0.2 -0.13 0.2" rpy="0 0 0"/>
    <geometry>
      <mesh filename="package://diff_H80_description/meshes/wheel_3.stl" scale="0.001 0.001 0.001"/>
    </geometry>
  </collision>
</link>

<joint name="diff_left_front" type="continuous">
  <origin xyz="-0.2 0.13 0.2" rpy="0 0 0"/>
  <parent link="base_link"/>
  <child link="wheel_1"/>
  <axis xyz="0.0 0.0 -1.0"/>
</joint>

<joint name="diff_left_rear" type="continuous">
  <origin xyz="0.2 0.13 0.2" rpy="0 0 0"/>
  <parent link="base_link"/>
  <child link="wheel_2"/>
  <axis xyz="0.0 0.0 -1.0"/>
</joint>

<joint name="diff_right_rear" type="continuous">
  <origin xyz="0.2 0.13 -0.2" rpy="0 0 0"/>
  <parent link="base_link"/>
  <child link="wheel_4"/>
  <axis xyz="0.0 0.0 1.0"/>
</joint>

<joint name="diff_right_front" type="continuous">
  <origin xyz="-0.2 0.13 -0.2" rpy="0 0 0"/>
  <parent link="base_link"/>
  <child link="wheel_3"/>
  <axis xyz="0.0 0.0 1.0"/>
</joint>

</robot>
